Workbook

Sheet PRODUTOS
A1: Código | B1: Produto | C1: Categoria | D1: Custo | E1: Preço venda | F1: Estoque mínimo
A2: P001 | B2: Teclado USB | C2: Informática | D2: 45,00 | E2: 89,90 | F2: 10
A3: P002 | B3: Mouse Óptico | C3: Informática | D3: 20,00 | E3: 49,90 | F3: 15
A4: P003 | B4: Caderno A4 | C4: Papelaria | D4: 8,00 | E4: 16,90 | F4: 20
G6: =IF(A6="","",D6+E6-F6) | H6: =IF(A6="","",VLOOKUP(A6,PRODUTOS!A:G,7,FALSE)) | I6: =IF(A6="","",IF(G6<=H6,"REPOR ESTOQUE","OK"))
G7: =IF(A7="","",D7+E7-F7) | H7: =IF(A7="","",VLOOKUP(A7,PRODUTOS!A:G,7,FALSE)) | I7: =IF(A7="","",IF(G7<=H7,"REPOR ESTOQUE","OK"))
G8: =IF(A8="","",D8+E8-F8) | H8: =IF(A8="","",VLOOKUP(A8,PRODUTOS!A:G,7,FALSE)) | I8: =IF(A8="","",IF(G8<=H8,"REPOR ESTOQUE","OK"))
G9: =IF(A9="","",D9+E9-F9) | H9: =IF(A9="","",VLOOKUP(A9,PRODUTOS!A:G,7,FALSE)) | I9: =IF(A9="","",IF(G9<=H9,"REPOR ESTOQUE","OK"))
G10: =IF(A10="","",D10+E10-F10) | H10: =IF(A10="","",VLOOKUP(A10,PRODUTOS!A:G,7,FALSE)) | I10: =IF(A10="","",IF(G10<=H10,"REPOR ESTOQUE","OK"))
G11: =IF(A11="","",D11+E11-F11) | H11: =IF(A11="","",VLOOKUP(A11,PRODUTOS!A:G,7,FALSE)) | I11: =IF(A11="","",IF(G11<=H11,"REPOR ESTOQUE","OK"))
G12: =IF(A12="","",D12+E12-F12) | H12: =IF(A12="","",VLOOKUP(A12,PRODUTOS!A:G,7,FALSE)) | I12: =IF(A12="","",IF(G12<=H12,"REPOR ESTOQUE","OK"))
G13: =IF(A13="","",D13+E13-F13) | H13: =IF(A13="","",VLOOKUP(A13,PRODUTOS!A:G,7,FALSE)) | I13: =IF(A13="","",IF(G13<=H13,"REPOR ESTOQUE","OK"))
G14: =IF(A14="","",D14+E14-F14) | H14: =IF(A14="","",VLOOKUP(A14,PRODUTOS!A:G,7,FALSE)) | I14: =IF(A14="","",IF(G14<=H14,"REPOR ESTOQUE","OK"))
G15: =IF(A15="","",D15+E15-F15) | H15: =IF(A15="","",VLOOKUP(A15,PRODUTOS!A:G,7,FALSE)) | I15: =IF(A15="","",IF(G15<=H15,"REPOR ESTOQUE","OK"))
G16: =IF(A16="","",D16+E16-F16) | H16: =IF(A16="","",VLOOKUP(A16,PRODUTOS!A:G,7,FALSE)) | I16: =IF(A16="","",IF(G16<=H16,"REPOR ESTOQUE","OK"))
G17: =IF(A17="","",D17+E17-F17) | H17: =IF(A17="","",VLOOKUP(A17,PRODUTOS!A:G,7,FALSE)) | I17: =IF(A17="","",IF(G17<=H17,"REPOR ESTOQUE","OK"))
... G21: =IF(A21="","",D21+E21-F21) | H21: =IF(A21="","",VLOOKUP(A21,PRODUTOS!A:G,7,FALSE)) | I21: =IF(A21="","",IF(G21<=H21,"REPOR ESTOQUE","OK"))
G22: =IF(A22="","",D22+E22-F22) | H22: =IF(A22="","",VLOOKUP(A22,PRODUTOS!A:G,7,FALSE))
G23: =IF(A23="","",D23+E23-F23) | H23: =IF(A23="","",VLOOKUP(A23,PRODUTOS!A:G,7,FALSE))
G24: =IF(A24="","",D24+E24-F24) | H24: =IF(A24="","",VLOOKUP(A24,PRODUTOS!A:G,7,FALSE))
G25: =IF(A25="","",D25+E25-F25) | H25: =IF(A25="","",VLOOKUP(A25,PRODUTOS!A:G,7,FALSE))
G26: =IF(A26="","",D26+E26-F26) | H26: =IF(A26="","",VLOOKUP(A26,PRODUTOS!A:G,7,FALSE))
G27: =IF(A27="","",D27+E27-F27) | H27: =IF(A27="","",VLOOKUP(A27,PRODUTOS!A:G,7,FALSE))
G28: =IF(A28="","",D28+E28-F28) | H28: =IF(A28="","",VLOOKUP(A28,PRODUTOS!A:G,7,FALSE))
G29: =IF(A29="","",D29+E29-F29) | H29: =IF(A29="","",VLOOKUP(A29,PRODUTOS!A:G,7,FALSE))
G30: =IF(A30="","",D30+E30-F30) | H30: =IF(A30="","",VLOOKUP(A30,PRODUTOS!A:G,7,FALSE))
G31: =IF(A31="","",D31+E31-F31) | H31: =IF(A31="","",VLOOKUP(A31,PRODUTOS!A:G,7,FALSE))
G32: =IF(A32="","",D32+E32-F32) | H32: =IF(A32="","",VLOOKUP(A32,PRODUTOS!A:G,7,FALSE))
G33: =IF(A33="","",D33+E33-F33)
G34: =IF(A34="","",D34+E34-F34)
G35: =IF(A35="","",D35+E35-F35)
G36: =IF(A36="","",D36+E36-F36)
G37: =IF(A37="","",D37+E37-F37)
G38: =IF(A38="","",D38+E38-F38)
G39: =IF(A39="","",D39+E39-F39)
G40: =IF(A40="","",D40+E40-F40)
G41: =IF(A41="","",D41+E41-F41)
G42: =IF(A42="","",D42+E42-F42)
G43: =IF(A43="","",D43+E43-F43)
G44: =IF(A44="","",D44+E44-F44)
...

Sheet MOVIMENTAÇÕES
A1: Data | B1: Tipo | C1: Código do Produto | D1: Quantidade | E1: Responsável | F1: Observação
A2: 15/10/2026 | B2: Entrada | C2: P001 | D2: 30 | E2: Vitor
A3: 15/10/2026 | B3: Entrada | C3: P002 | D3: 40 | E3: Vitor
A4: 15/10/2026 | B4: Saída | C4: P001 | D4: 5 | E4: Vitor
A5: 15/10/2026 | B5: Entrada | C5: P003 | D5: 50 | E5: Vitor

Sheet ESTOQUE
A1: Código | B1: Produto | C1: Categoria | D1: Estoque Inicial | E1: Entradas | F1: Saídas | G1: Estoque Atual | H1: Estoque Mínimo | I1: Status
A2: =PRODUTOS!A2 -> P001 | B2: =IF(A2="","",IFERROR(VLOOKUP(A2,PRODUTOS!A:B,2,FALSE),"")) -> Teclado USB | C2: =IF(A2="","",IFERROR(VLOOKUP(A2,PRODUTOS!A:C,3,FALSE),"")) -> Informática | D2: 1 | E2: =IF(A2="","",IFERROR(SUMIFS('MOVIMENTAÇÕES'!D:D,'MOVIMENTAÇÕES'!C:C,A2,'MOVIMENTAÇÕES'!B:B,"Entrada"),"")) -> 30 | F2: 50 | G2: =IF(A2="","",IFERROR(D3+E2-F2,"")) -> -18 | H2: =PRODUTOS!F2 -> 10 | I2: =IF(A2="","",IFERROR(IF(G2<=H2,"REPOR ESTOQUE","OK"),"")) -> REPOR ESTOQUE
A3: =PRODUTOS!A3 -> P002 | B3: =IF(A3="","",IFERROR(VLOOKUP(A3,PRODUTOS!A:B,2,FALSE),"")) -> Mouse Óptico | C3: =IF(A3="","",IFERROR(VLOOKUP(A3,PRODUTOS!A:C,3,FALSE),"")) -> Informática | D3: 2 | E3: =IF(A3="","",IFERROR(SUMIFS('MOVIMENTAÇÕES'!D:D,'MOVIMENTAÇÕES'!C:C,A3,'MOVIMENTAÇÕES'!B:B,"Entrada"),"")) -> 40 | F3: =IF(A3="","",IFERROR(SUMIFS('MOVIMENTAÇÕES'!D:D,'MOVIMENTAÇÕES'!C:C,A3,'MOVIMENTAÇÕES'!B:B,"Saída"),"")) -> 0 | G3: =IF(A3="","",IFERROR(#REF!+E3-F3,"")) | H3: =PRODUTOS!F3 -> 15 | I3: =IF(A3="","",IFERROR(IF(G3<=H3,"REPOR ESTOQUE","OK"),"")) -> OK
A4: =PRODUTOS!A4 -> P003 | B4: =IF(A4="","",IFERROR(VLOOKUP(A4,PRODUTOS!A:B,2,FALSE),"")) -> Caderno A4 | C4: =IF(A4="","",IFERROR(VLOOKUP(A4,PRODUTOS!A:C,3,FALSE),"")) -> Papelaria | D4: 0 | E4: =IF(A4="","",IFERROR(SUMIFS('MOVIMENTAÇÕES'!D:D,'MOVIMENTAÇÕES'!C:C,A4,'MOVIMENTAÇÕES'!B:B,"Entrada"),"")) -> 50 | F4: =IF(A4="","",IFERROR(SUMIFS('MOVIMENTAÇÕES'!D:D,'MOVIMENTAÇÕES'!C:C,A4,'MOVIMENTAÇÕES'!B:B,"Saída"),"")) -> 0 | G4: =IF(A4="","",IFERROR(D4+E4-F4,"")) -> 50 | H4: =PRODUTOS!F4 -> 20 | I4: =IF(A4="","",IFERROR(IF(G4<=H4,"REPOR ESTOQUE","OK"),"")) -> OK
A5: =PRODUTOS!A5 | B5: =IF(A5="","",IFERROR(VLOOKUP(A5,PRODUTOS!A:B,2,FALSE),"")) | C5: =IF(A5="","",IFERROR(VLOOKUP(A5,PRODUTOS!A:C,3,FALSE),"")) | D5: 0 | E5: =IF(A5="","",IFERROR(SUMIFS('MOVIMENTAÇÕES'!D:D,'MOVIMENTAÇÕES'!C:C,A5,'MOVIMENTAÇÕES'!B:B,"Entrada"),"")) | F5: =IF(A5="","",IFERROR(SUMIFS('MOVIMENTAÇÕES'!D:D,'MOVIMENTAÇÕES'!C:C,A5,'MOVIMENTAÇÕES'!B:B,"Saída"),"")) | G5: =IF(A5="","",IFERROR(D5+E5-F5,"")) | H5: =PRODUTOS!F5 | I5: =IF(A5="","",IFERROR(IF(G5<=H5,"REPOR ESTOQUE","OK"),""))
A6: =PRODUTOS!A6 | B6: =IF(A6="","",IFERROR(VLOOKUP(A6,PRODUTOS!A:B,2,FALSE),"")) | C6: =IF(A6="","",IFERROR(VLOOKUP(A6,PRODUTOS!A:C,3,FALSE),"")) | D6: 0 | E6: =IF(A6="","",IFERROR(SUMIFS('MOVIMENTAÇÕES'!D:D,'MOVIMENTAÇÕES'!C:C,A6,'MOVIMENTAÇÕES'!B:B,"Entrada"),"")) | F6: =IF(A6="","",IFERROR(SUMIFS('MOVIMENTAÇÕES'!D:D,'MOVIMENTAÇÕES'!C:C,A6,'MOVIMENTAÇÕES'!B:B,"Saída"),"")) | G6: =IF(A6="","",IFERROR(D6+E6-F6,"")) | H6: =PRODUTOS!F6 | I6: =IF(A6="","",IFERROR(IF(G6<=H6,"REPOR ESTOQUE","OK"),""))
A7: =PRODUTOS!A7 | B7: =IF(A7="","",IFERROR(VLOOKUP(A7,PRODUTOS!A:B,2,FALSE),"")) | C7: =IF(A7="","",IFERROR(VLOOKUP(A7,PRODUTOS!A:C,3,FALSE),"")) | D7: 0 | E7: =IF(A7="","",IFERROR(SUMIFS('MOVIMENTAÇÕES'!D:D,'MOVIMENTAÇÕES'!C:C,A7,'MOVIMENTAÇÕES'!B:B,"Entrada"),"")) | F7: =IF(A7="","",IFERROR(SUMIFS('MOVIMENTAÇÕES'!D:D,'MOVIMENTAÇÕES'!C:C,A7,'MOVIMENTAÇÕES'!B:B,"Saída"),"")) | G7: =IF(A7="","",IFERROR(D7+E7-F7,"")) | H7: =PRODUTOS!F7 | I7: =IF(A7="","",IFERROR(IF(G7<=H7,"REPOR ESTOQUE","OK"),""))
A8: =PRODUTOS!A8 | B8: =IF(A8="","",IFERROR(VLOOKUP(A8,PRODUTOS!A:B,2,FALSE),"")) | C8: =IF(A8="","",IFERROR(VLOOKUP(A8,PRODUTOS!A:C,3,FALSE),"")) | D8: 0 | E8: =IF(A8="","",IFERROR(SUMIFS('MOVIMENTAÇÕES'!D:D,'MOVIMENTAÇÕES'!C:C,A8,'MOVIMENTAÇÕES'!B:B,"Entrada"),"")) | F8: =IF(A8="","",IFERROR(SUMIFS('MOVIMENTAÇÕES'!D:D,'MOVIMENTAÇÕES'!C:C,A8,'MOVIMENTAÇÕES'!B:B,"Saída"),"")) | G8: =IF(A8="","",IFERROR(D8+E8-F8,"")) | H8: =PRODUTOS!F8 | I8: =IF(A8="","",IFERROR(IF(G8<=H8,"REPOR ESTOQUE","OK"),""))
A9: =PRODUTOS!A9 | B9: =IF(A9="","",IFERROR(VLOOKUP(A9,PRODUTOS!A:B,2,FALSE),"")) | C9: =IF(A9="","",IFERROR(VLOOKUP(A9,PRODUTOS!A:C,3,FALSE),"")) | E9: =IF(A9="","",IFERROR(SUMIFS('MOVIMENTAÇÕES'!D:D,'MOVIMENTAÇÕES'!C:C,A9,'MOVIMENTAÇÕES'!B:B,"Entrada"),"")) | F9: =IF(A9="","",IFERROR(SUMIFS('MOVIMENTAÇÕES'!D:D,'MOVIMENTAÇÕES'!C:C,A9,'MOVIMENTAÇÕES'!B:B,"Saída"),"")) | G9: =IF(A9="","",IFERROR(D9+E9-F9,"")) | H9: =PRODUTOS!F9 | I9: =IF(A9="","",IFERROR(IF(G9<=H9,"REPOR ESTOQUE","OK"),""))
A10: =PRODUTOS!A10 | B10: =IF(A10="","",IFERROR(VLOOKUP(A10,PRODUTOS!A:B,2,FALSE),"")) | C10: =IF(A10="","",IFERROR(VLOOKUP(A10,PRODUTOS!A:C,3,FALSE),"")) | E10: =IF(A10="","",IFERROR(SUMIFS('MOVIMENTAÇÕES'!D:D,'MOVIMENTAÇÕES'!C:C,A10,'MOVIMENTAÇÕES'!B:B,"Entrada"),"")) | F10: =IF(A10="","",IFERROR(SUMIFS('MOVIMENTAÇÕES'!D:D,'MOVIMENTAÇÕES'!C:C,A10,'MOVIMENTAÇÕES'!B:B,"Saída"),"")) | G10: =IF(A10="","",IFERROR(D10+E10-F10,"")) | H10: =PRODUTOS!F10 | I10: =IF(A10="","",IFERROR(IF(G10<=H10,"REPOR ESTOQUE","OK"),""))
A11: =PRODUTOS!A11 | B11: =IF(A11="","",IFERROR(VLOOKUP(A11,PRODUTOS!A:B,2,FALSE),"")) | C11: =IF(A11="","",IFERROR(VLOOKUP(A11,PRODUTOS!A:C,3,FALSE),"")) | E11: =IF(A11="","",IFERROR(SUMIFS('MOVIMENTAÇÕES'!D:D,'MOVIMENTAÇÕES'!C:C,A11,'MOVIMENTAÇÕES'!B:B,"Entrada"),"")) | F11: =IF(A11="","",IFERROR(SUMIFS('MOVIMENTAÇÕES'!D:D,'MOVIMENTAÇÕES'!C:C,A11,'MOVIMENTAÇÕES'!B:B,"Saída"),"")) | G11: =IF(A11="","",IFERROR(D11+E11-F11,"")) | H11: =PRODUTOS!F11 | I11: =IF(A11="","",IFERROR(IF(G11<=H11,"REPOR ESTOQUE","OK"),""))
A12: =PRODUTOS!A12 | B12: =IF(A12="","",IFERROR(VLOOKUP(A12,PRODUTOS!A:B,2,FALSE),"")) | C12: =IF(A12="","",IFERROR(VLOOKUP(A12,PRODUTOS!A:C,3,FALSE),"")) | E12: =IF(A12="","",IFERROR(SUMIFS('MOVIMENTAÇÕES'!D:D,'MOVIMENTAÇÕES'!C:C,A12,'MOVIMENTAÇÕES'!B:B,"Entrada"),"")) | F12: =IF(A12="","",IFERROR(SUMIFS('MOVIMENTAÇÕES'!D:D,'MOVIMENTAÇÕES'!C:C,A12,'MOVIMENTAÇÕES'!B:B,"Saída"),"")) | G12: =IF(A12="","",IFERROR(D12+E12-F12,"")) | H12: =PRODUTOS!F12 | I12: =IF(A12="","",IFERROR(IF(G12<=H12,"REPOR ESTOQUE","OK"),""))
A13: =PRODUTOS!A13 | B13: =IF(A13="","",IFERROR(VLOOKUP(A13,PRODUTOS!A:B,2,FALSE),"")) | C13: =IF(A13="","",IFERROR(VLOOKUP(A13,PRODUTOS!A:C,3,FALSE),"")) | E13: =IF(A13="","",IFERROR(SUMIFS('MOVIMENTAÇÕES'!D:D,'MOVIMENTAÇÕES'!C:C,A13,'MOVIMENTAÇÕES'!B:B,"Entrada"),"")) | F13: =IF(A13="","",IFERROR(SUMIFS('MOVIMENTAÇÕES'!D:D,'MOVIMENTAÇÕES'!C:C,A13,'MOVIMENTAÇÕES'!B:B,"Saída"),"")) | G13: =IF(A13="","",IFERROR(D13+E13-F13,"")) | H13: =PRODUTOS!F13 | I13: =IF(A13="","",IFERROR(IF(G13<=H13,"REPOR ESTOQUE","OK"),""))
A14: =PRODUTOS!A14 | B14: =IF(A14="","",IFERROR(VLOOKUP(A14,PRODUTOS!A:B,2,FALSE),"")) | C14: =IF(A14="","",IFERROR(VLOOKUP(A14,PRODUTOS!A:C,3,FALSE),"")) | E14: =IF(A14="","",IFERROR(SUMIFS('MOVIMENTAÇÕES'!D:D,'MOVIMENTAÇÕES'!C:C,A14,'MOVIMENTAÇÕES'!B:B,"Entrada"),"")) | F14: =IF(A14="","",IFERROR(SUMIFS('MOVIMENTAÇÕES'!D:D,'MOVIMENTAÇÕES'!C:C,A14,'MOVIMENTAÇÕES'!B:B,"Saída"),"")) | G14: =IF(A14="","",IFERROR(D14+E14-F14,"")) | H14: =PRODUTOS!F14 | I14: =IF(A14="","",IFERROR(IF(G14<=H14,"REPOR ESTOQUE","OK"),""))
A15: =PRODUTOS!A15 | B15: =IF(A15="","",IFERROR(VLOOKUP(A15,PRODUTOS!A:B,2,FALSE),"")) | C15: =IF(A15="","",IFERROR(VLOOKUP(A15,PRODUTOS!A:C,3,FALSE),"")) | E15: =IF(A15="","",IFERROR(SUMIFS('MOVIMENTAÇÕES'!D:D,'MOVIMENTAÇÕES'!C:C,A15,'MOVIMENTAÇÕES'!B:B,"Entrada"),"")) | F15: =IF(A15="","",IFERROR(SUMIFS('MOVIMENTAÇÕES'!D:D,'MOVIMENTAÇÕES'!C:C,A15,'MOVIMENTAÇÕES'!B:B,"Saída"),"")) | G15: =IF(A15="","",IFERROR(D15+E15-F15,"")) | H15: =PRODUTOS!F15 | I15: =IF(A15="","",IFERROR(IF(G15<=H15,"REPOR ESTOQUE","OK"),""))
A16: =PRODUTOS!A16 | B16: =IF(A16="","",IFERROR(VLOOKUP(A16,PRODUTOS!A:B,2,FALSE),"")) | C16: =IF(A16="","",IFERROR(VLOOKUP(A16,PRODUTOS!A:C,3,FALSE),"")) | E16: =IF(A16="","",IFERROR(SUMIFS('MOVIMENTAÇÕES'!D:D,'MOVIMENTAÇÕES'!C:C,A16,'MOVIMENTAÇÕES'!B:B,"Entrada"),"")) | F16: =IF(A16="","",IFERROR(SUMIFS('MOVIMENTAÇÕES'!D:D,'MOVIMENTAÇÕES'!C:C,A16,'MOVIMENTAÇÕES'!B:B,"Saída"),"")) | G16: =IF(A16="","",IFERROR(D16+E16-F16,"")) | H16: =PRODUTOS!F16 | I16: =IF(A16="","",IFERROR(IF(G16<=H16,"REPOR ESTOQUE","OK"),""))
A17: =PRODUTOS!A17 | B17: =IF(A17="","",IFERROR(VLOOKUP(A17,PRODUTOS!A:B,2,FALSE),"")) | C17: =IF(A17="","",IFERROR(VLOOKUP(A17,PRODUTOS!A:C,3,FALSE),"")) | E17: =IF(A17="","",IFERROR(SUMIFS('MOVIMENTAÇÕES'!D:D,'MOVIMENTAÇÕES'!C:C,A17,'MOVIMENTAÇÕES'!B:B,"Entrada"),"")) | F17: =IF(A17="","",IFERROR(SUMIFS('MOVIMENTAÇÕES'!D:D,'MOVIMENTAÇÕES'!C:C,A17,'MOVIMENTAÇÕES'!B:B,"Saída"),"")) | G17: =IF(A17="","",IFERROR(D17+E17-F17,"")) | H17: =PRODUTOS!F17 | I17: =IF(A17="","",IFERROR(IF(G17<=H17,"REPOR ESTOQUE","OK"),""))
A18: =PRODUTOS!A18 | B18: =IF(A18="","",IFERROR(VLOOKUP(A18,PRODUTOS!A:B,2,FALSE),"")) | C18: =IF(A18="","",IFERROR(VLOOKUP(A18,PRODUTOS!A:C,3,FALSE),"")) | E18: =IF(A18="","",IFERROR(SUMIFS('MOVIMENTAÇÕES'!D:D,'MOVIMENTAÇÕES'!C:C,A18,'MOVIMENTAÇÕES'!B:B,"Entrada"),"")) | F18: =IF(A18="","",IFERROR(SUMIFS('MOVIMENTAÇÕES'!D:D,'MOVIMENTAÇÕES'!C:C,A18,'MOVIMENTAÇÕES'!B:B,"Saída"),"")) | G18: =IF(A18="","",IFERROR(D18+E18-F18,"")) | H18: =PRODUTOS!F18 | I18: =IF(A18="","",IFERROR(IF(G18<=H18,"REPOR ESTOQUE","OK"),""))
A19: =PRODUTOS!A19 | B19: =IF(A19="","",IFERROR(VLOOKUP(A19,PRODUTOS!A:B,2,FALSE),"")) | C19: =IF(A19="","",IFERROR(VLOOKUP(A19,PRODUTOS!A:C,3,FALSE),"")) | E19: =IF(A19="","",IFERROR(SUMIFS('MOVIMENTAÇÕES'!D:D,'MOVIMENTAÇÕES'!C:C,A19,'MOVIMENTAÇÕES'!B:B,"Entrada"),"")) | F19: =IF(A19="","",IFERROR(SUMIFS('MOVIMENTAÇÕES'!D:D,'MOVIMENTAÇÕES'!C:C,A19,'MOVIMENTAÇÕES'!B:B,"Saída"),"")) | G19: =IF(A19="","",IFERROR(D19+E19-F19,"")) | H19: =PRODUTOS!F19 | I19: =IF(A19="","",IFERROR(IF(G19<=H19,"REPOR ESTOQUE","OK"),""))
A20: =PRODUTOS!A20 | B20: =IF(A20="","",IFERROR(VLOOKUP(A20,PRODUTOS!A:B,2,FALSE),"")) | C20: =IF(A20="","",IFERROR(VLOOKUP(A20,PRODUTOS!A:C,3,FALSE),"")) | E20: =IF(A20="","",IFERROR(SUMIFS('MOVIMENTAÇÕES'!D:D,'MOVIMENTAÇÕES'!C:C,A20,'MOVIMENTAÇÕES'!B:B,"Entrada"),"")) | F20: =IF(A20="","",IFERROR(SUMIFS('MOVIMENTAÇÕES'!D:D,'MOVIMENTAÇÕES'!C:C,A20,'MOVIMENTAÇÕES'!B:B,"Saída"),"")) | G20: =IF(A20="","",IFERROR(D20+E20-F20,"")) | H20: =PRODUTOS!F20 | I20: =IF(A20="","",IFERROR(IF(G20<=H20,"REPOR ESTOQUE","OK"),""))
A21: =PRODUTOS!A21 | B21: =IF(A21="","",IFERROR(VLOOKUP(A21,PRODUTOS!A:B,2,FALSE),"")) | C21: =IF(A21="","",IFERROR(VLOOKUP(A21,PRODUTOS!A:C,3,FALSE),"")) | E21: =IF(A21="","",IFERROR(SUMIFS('MOVIMENTAÇÕES'!D:D,'MOVIMENTAÇÕES'!C:C,A21,'MOVIMENTAÇÕES'!B:B,"Entrada"),"")) | F21: =IF(A21="","",IFERROR(SUMIFS('MOVIMENTAÇÕES'!D:D,'MOVIMENTAÇÕES'!C:C,A21,'MOVIMENTAÇÕES'!B:B,"Saída"),"")) | G21: =IF(A21="","",IFERROR(D21+E21-F21,"")) | H21: =PRODUTOS!F21 | I21: =IF(A21="","",IFERROR(IF(G21<=H21,"REPOR ESTOQUE","OK"),""))
A22: =PRODUTOS!A22 | B22: =IF(A22="","",IFERROR(VLOOKUP(A22,PRODUTOS!A:B,2,FALSE),"")) | C22: =IF(A22="","",IFERROR(VLOOKUP(A22,PRODUTOS!A:C,3,FALSE),"")) | E22: =IF(A22="","",IFERROR(SUMIFS('MOVIMENTAÇÕES'!D:D,'MOVIMENTAÇÕES'!C:C,A22,'MOVIMENTAÇÕES'!B:B,"Entrada"),"")) | F22: =IF(A22="","",IFERROR(SUMIFS('MOVIMENTAÇÕES'!D:D,'MOVIMENTAÇÕES'!C:C,A22,'MOVIMENTAÇÕES'!B:B,"Saída"),"")) | G22: =IF(A22="","",IFERROR(D22+E22-F22,"")) | H22: =IF(A22="","",VLOOKUP(A22,PRODUTOS!A:G,7,FALSE)) | I22: =IF(A22="","",IFERROR(IF(G22<=H22,"REPOR ESTOQUE","OK"),""))
A23: =PRODUTOS!A23 | B23: =IF(A23="","",IFERROR(VLOOKUP(A23,PRODUTOS!A:B,2,FALSE),"")) | C23: =IF(A23="","",IFERROR(VLOOKUP(A23,PRODUTOS!A:C,3,FALSE),"")) | E23: =IF(A23="","",IFERROR(SUMIFS('MOVIMENTAÇÕES'!D:D,'MOVIMENTAÇÕES'!C:C,A23,'MOVIMENTAÇÕES'!B:B,"Entrada"),"")) | F23: =IF(A23="","",IFERROR(SUMIFS('MOVIMENTAÇÕES'!D:D,'MOVIMENTAÇÕES'!C:C,A23,'MOVIMENTAÇÕES'!B:B,"Saída"),"")) | G23: =IF(A23="","",IFERROR(D23+E23-F23,"")) | H23: =IF(A23="","",VLOOKUP(A23,PRODUTOS!A:G,7,FALSE)) | I23: =IF(A23="","",IFERROR(IF(G23<=H23,"REPOR ESTOQUE","OK"),""))
A24: =PRODUTOS!A24 | B24: =IF(A24="","",IFERROR(VLOOKUP(A24,PRODUTOS!A:B,2,FALSE),"")) | C24: =IF(A24="","",IFERROR(VLOOKUP(A24,PRODUTOS!A:C,3,FALSE),"")) | E24: =IF(A24="","",IFERROR(SUMIFS('MOVIMENTAÇÕES'!D:D,'MOVIMENTAÇÕES'!C:C,A24,'MOVIMENTAÇÕES'!B:B,"Entrada"),"")) | F24: =IF(A24="","",IFERROR(SUMIFS('MOVIMENTAÇÕES'!D:D,'MOVIMENTAÇÕES'!C:C,A24,'MOVIMENTAÇÕES'!B:B,"Saída"),"")) | G24: =IF(A24="","",IFERROR(D24+E24-F24,"")) | H24: =IF(A24="","",VLOOKUP(A24,PRODUTOS!A:G,7,FALSE)) | I24: =IF(A24="","",IFERROR(IF(G24<=H24,"REPOR ESTOQUE","OK"),""))
A25: =PRODUTOS!A25 | B25: =IF(A25="","",IFERROR(VLOOKUP(A25,PRODUTOS!A:B,2,FALSE),"")) | C25: =IF(A25="","",IFERROR(VLOOKUP(A25,PRODUTOS!A:C,3,FALSE),"")) | E25: =IF(A25="","",IFERROR(SUMIFS('MOVIMENTAÇÕES'!D:D,'MOVIMENTAÇÕES'!C:C,A25,'MOVIMENTAÇÕES'!B:B,"Entrada"),"")) | F25: =IF(A25="","",IFERROR(SUMIFS('MOVIMENTAÇÕES'!D:D,'MOVIMENTAÇÕES'!C:C,A25,'MOVIMENTAÇÕES'!B:B,"Saída"),"")) | G25: =IF(A25="","",IFERROR(D25+E25-F25,"")) | H25: =IF(A25="","",VLOOKUP(A25,PRODUTOS!A:G,7,FALSE)) | I25: =IF(A25="","",IFERROR(IF(G25<=H25,"REPOR ESTOQUE","OK"),""))
A26: =PRODUTOS!A26 | B26: =IF(A26="","",IFERROR(VLOOKUP(A26,PRODUTOS!A:B,2,FALSE),"")) | C26: =IF(A26="","",IFERROR(VLOOKUP(A26,PRODUTOS!A:C,3,FALSE),"")) | E26: =IF(A26="","",IFERROR(SUMIFS('MOVIMENTAÇÕES'!D:D,'MOVIMENTAÇÕES'!C:C,A26,'MOVIMENTAÇÕES'!B:B,"Entrada"),"")) | F26: =IF(A26="","",IFERROR(SUMIFS('MOVIMENTAÇÕES'!D:D,'MOVIMENTAÇÕES'!C:C,A26,'MOVIMENTAÇÕES'!B:B,"Saída"),"")) | G26: =IF(A26="","",IFERROR(D26+E26-F26,"")) | H26: =IF(A26="","",VLOOKUP(A26,PRODUTOS!A:G,7,FALSE)) | I26: =IF(A26="","",IFERROR(IF(G26<=H26,"REPOR ESTOQUE","OK"),""))
A27: =PRODUTOS!A27 | B27: =IF(A27="","",IFERROR(VLOOKUP(A27,PRODUTOS!A:B,2,FALSE),"")) | C27: =IF(A27="","",IFERROR(VLOOKUP(A27,PRODUTOS!A:C,3,FALSE),"")) | E27: =IF(A27="","",IFERROR(SUMIFS('MOVIMENTAÇÕES'!D:D,'MOVIMENTAÇÕES'!C:C,A27,'MOVIMENTAÇÕES'!B:B,"Entrada"),"")) | F27: =IF(A27="","",IFERROR(SUMIFS('MOVIMENTAÇÕES'!D:D,'MOVIMENTAÇÕES'!C:C,A27,'MOVIMENTAÇÕES'!B:B,"Saída"),"")) | G27: =IF(A27="","",IFERROR(D27+E27-F27,"")) | H27: =IF(A27="","",VLOOKUP(A27,PRODUTOS!A:G,7,FALSE)) | I27: =IF(A27="","",IFERROR(IF(G27<=H27,"REPOR ESTOQUE","OK"),""))
A28: =PRODUTOS!A28 | B28: =IF(A28="","",IFERROR(VLOOKUP(A28,PRODUTOS!A:B,2,FALSE),"")) | C28: =IF(A28="","",IFERROR(VLOOKUP(A28,PRODUTOS!A:C,3,FALSE),"")) | E28: =IF(A28="","",IFERROR(SUMIFS('MOVIMENTAÇÕES'!D:D,'MOVIMENTAÇÕES'!C:C,A28,'MOVIMENTAÇÕES'!B:B,"Entrada"),"")) | F28: =IF(A28="","",IFERROR(SUMIFS('MOVIMENTAÇÕES'!D:D,'MOVIMENTAÇÕES'!C:C,A28,'MOVIMENTAÇÕES'!B:B,"Saída"),"")) | G28: =IF(A28="","",IFERROR(D28+E28-F28,"")) | H28: =IF(A28="","",VLOOKUP(A28,PRODUTOS!A:G,7,FALSE)) | I28: =IF(A28="","",IFERROR(IF(G28<=H28,"REPOR ESTOQUE","OK"),""))
A29: =PRODUTOS!A29 | B29: =IF(A29="","",IFERROR(VLOOKUP(A29,PRODUTOS!A:B,2,FALSE),"")) | C29: =IF(A29="","",IFERROR(VLOOKUP(A29,PRODUTOS!A:C,3,FALSE),"")) | E29: =IF(A29="","",IFERROR(SUMIFS('MOVIMENTAÇÕES'!D:D,'MOVIMENTAÇÕES'!C:C,A29,'MOVIMENTAÇÕES'!B:B,"Entrada"),"")) | F29: =IF(A29="","",IFERROR(SUMIFS('MOVIMENTAÇÕES'!D:D,'MOVIMENTAÇÕES'!C:C,A29,'MOVIMENTAÇÕES'!B:B,"Saída"),"")) | G29: =IF(A29="","",IFERROR(D29+E29-F29,"")) | H29: =IF(A29="","",VLOOKUP(A29,PRODUTOS!A:G,7,FALSE)) | I29: =IF(A29="","",IFERROR(IF(G29<=H29,"REPOR ESTOQUE","OK"),""))
A30: =PRODUTOS!A30 | B30: =IF(A30="","",IFERROR(VLOOKUP(A30,PRODUTOS!A:B,2,FALSE),"")) | C30: =IF(A30="","",IFERROR(VLOOKUP(A30,PRODUTOS!A:C,3,FALSE),"")) | E30: =IF(A30="","",IFERROR(SUMIFS('MOVIMENTAÇÕES'!D:D,'MOVIMENTAÇÕES'!C:C,A30,'MOVIMENTAÇÕES'!B:B,"Entrada"),"")) | F30: =IF(A30="","",IFERROR(SUMIFS('MOVIMENTAÇÕES'!D:D,'MOVIMENTAÇÕES'!C:C,A30,'MOVIMENTAÇÕES'!B:B,"Saída"),"")) | G30: =IF(A30="","",IFERROR(D30+E30-F30,"")) | H30: =IF(A30="","",VLOOKUP(A30,PRODUTOS!A:G,7,FALSE)) | I30: =IF(A30="","",IFERROR(IF(G30<=H30,"REPOR ESTOQUE","OK"),""))
A31: =PRODUTOS!A31 | B31: =IF(A31="","",IFERROR(VLOOKUP(A31,PRODUTOS!A:B,2,FALSE),"")) | C31: =IF(A31="","",IFERROR(VLOOKUP(A31,PRODUTOS!A:C,3,FALSE),"")) | E31: =IF(A31="","",IFERROR(SUMIFS('MOVIMENTAÇÕES'!D:D,'MOVIMENTAÇÕES'!C:C,A31,'MOVIMENTAÇÕES'!B:B,"Entrada"),"")) | F31: =IF(A31="","",IFERROR(SUMIFS('MOVIMENTAÇÕES'!D:D,'MOVIMENTAÇÕES'!C:C,A31,'MOVIMENTAÇÕES'!B:B,"Saída"),"")) | G31: =IF(A31="","",IFERROR(D31+E31-F31,"")) | H31: =IF(A31="","",VLOOKUP(A31,PRODUTOS!A:G,7,FALSE)) | I31: =IF(A31="","",IFERROR(IF(G31<=H31,"REPOR ESTOQUE","OK"),""))
A32: =PRODUTOS!A32 | B32: =IF(A32="","",IFERROR(VLOOKUP(A32,PRODUTOS!A:B,2,FALSE),"")) | C32: =IF(A32="","",IFERROR(VLOOKUP(A32,PRODUTOS!A:C,3,FALSE),"")) | E32: =IF(A32="","",IFERROR(SUMIFS('MOVIMENTAÇÕES'!D:D,'MOVIMENTAÇÕES'!C:C,A32,'MOVIMENTAÇÕES'!B:B,"Entrada"),"")) | F32: =IF(A32="","",IFERROR(SUMIFS('MOVIMENTAÇÕES'!D:D,'MOVIMENTAÇÕES'!C:C,A32,'MOVIMENTAÇÕES'!B:B,"Saída"),"")) | G32: =IF(A32="","",IFERROR(D32+E32-F32,"")) | H32: =IF(A32="","",VLOOKUP(A32,PRODUTOS!A:G,7,FALSE)) | I32: =IF(A32="","",IFERROR(IF(G32<=H32,"REPOR ESTOQUE","OK"),""))
A33: =PRODUTOS!A33 | B33: =IF(A33="","",IFERROR(VLOOKUP(A33,PRODUTOS!A:B,2,FALSE),"")) | C33: =IF(A33="","",IFERROR(VLOOKUP(A33,PRODUTOS!A:C,3,FALSE),"")) | E33: =IF(A33="","",IFERROR(SUMIFS('MOVIMENTAÇÕES'!D:D,'MOVIMENTAÇÕES'!C:C,A33,'MOVIMENTAÇÕES'!B:B,"Entrada"),"")) | F33: =IF(A33="","",IFERROR(SUMIFS('MOVIMENTAÇÕES'!D:D,'MOVIMENTAÇÕES'!C:C,A33,'MOVIMENTAÇÕES'!B:B,"Saída"),"")) | G33: =IF(A33="","",IFERROR(D33+E33-F33,"")) | H33: =IF(A33="","",VLOOKUP(A33,PRODUTOS!A:G,7,FALSE)) | I33: =IF(A33="","",IFERROR(IF(G33<=H33,"REPOR ESTOQUE","OK"),""))
... A40: =PRODUTOS!A40 | B40: =IF(A40="","",IFERROR(VLOOKUP(A40,PRODUTOS!A:B,2,FALSE),"")) | C40: =IF(A40="","",IFERROR(VLOOKUP(A40,PRODUTOS!A:C,3,FALSE),"")) | E40: =IF(A40="","",IFERROR(SUMIFS('MOVIMENTAÇÕES'!D:D,'MOVIMENTAÇÕES'!C:C,A40,'MOVIMENTAÇÕES'!B:B,"Entrada"),"")) | F40: =IF(A40="","",IFERROR(SUMIFS('MOVIMENTAÇÕES'!D:D,'MOVIMENTAÇÕES'!C:C,A40,'MOVIMENTAÇÕES'!B:B,"Saída"),"")) | G40: =IF(A40="","",IFERROR(D40+E40-F40,"")) | H40: =IF(A40="","",VLOOKUP(A40,PRODUTOS!A:G,7,FALSE)) | I40: =IF(A40="","",IFERROR(IF(G40<=H40,"REPOR ESTOQUE","OK"),""))
A41: =IFERROR(FILTRO(PRODUTOS!A41:A1000,PRODUTOS!A41:A1000<>""),"") | B41: =IF(A41="","",IFERROR(VLOOKUP(A41,PRODUTOS!A:B,2,FALSE),"")) | C41: =IF(A41="","",IFERROR(VLOOKUP(A41,PRODUTOS!A:C,3,FALSE),"")) | E41: =IF(A41="","",IFERROR(SUMIFS('MOVIMENTAÇÕES'!D:D,'MOVIMENTAÇÕES'!C:C,A41,'MOVIMENTAÇÕES'!B:B,"Entrada"),"")) | F41: =IF(A41="","",IFERROR(SUMIFS('MOVIMENTAÇÕES'!D:D,'MOVIMENTAÇÕES'!C:C,A41,'MOVIMENTAÇÕES'!B:B,"Saída"),"")) | G41: =IF(A41="","",IFERROR(D41+E41-F41,"")) | H41: =IF(A41="","",VLOOKUP(A41,PRODUTOS!A:G,7,FALSE)) | I41: =IF(A41="","",IFERROR(IF(G41<=H41,"REPOR ESTOQUE","OK"),""))
A42: =IFERROR(FILTRO(PRODUTOS!A42:A1000,PRODUTOS!A42:A1000<>""),"") | B42: =IF(A42="","",IFERROR(VLOOKUP(A42,PRODUTOS!A:B,2,FALSE),"")) | C42: =IF(A42="","",IFERROR(VLOOKUP(A42,PRODUTOS!A:C,3,FALSE),"")) | E42: =IF(A42="","",IFERROR(SUMIFS('MOVIMENTAÇÕES'!D:D,'MOVIMENTAÇÕES'!C:C,A42,'MOVIMENTAÇÕES'!B:B,"Entrada"),"")) | F42: =IF(A42="","",IFERROR(SUMIFS('MOVIMENTAÇÕES'!D:D,'MOVIMENTAÇÕES'!C:C,A42,'MOVIMENTAÇÕES'!B:B,"Saída"),"")) | G42: =IF(A42="","",IFERROR(D42+E42-F42,"")) | H42: =IF(A42="","",VLOOKUP(A42,PRODUTOS!A:G,7,FALSE)) | I42: =IF(A42="","",IFERROR(IF(G42<=H42,"REPOR ESTOQUE","OK"),""))
A43: =IFERROR(FILTRO(PRODUTOS!A43:A1000,PRODUTOS!A43:A1000<>""),"") | B43: =IF(A43="","",IFERROR(VLOOKUP(A43,PRODUTOS!A:B,2,FALSE),"")) | C43: =IF(A43="","",IFERROR(VLOOKUP(A43,PRODUTOS!A:C,3,FALSE),"")) | E43: =IF(A43="","",IFERROR(SUMIFS('MOVIMENTAÇÕES'!D:D,'MOVIMENTAÇÕES'!C:C,A43,'MOVIMENTAÇÕES'!B:B,"Entrada"),"")) | F43: =IF(A43="","",IFERROR(SUMIFS('MOVIMENTAÇÕES'!D:D,'MOVIMENTAÇÕES'!C:C,A43,'MOVIMENTAÇÕES'!B:B,"Saída"),"")) | G43: =IF(A43="","",IFERROR(D43+E43-F43,"")) | H43: =IF(A43="","",VLOOKUP(A43,PRODUTOS!A:G,7,FALSE)) | I43: =IF(A43="","",IFERROR(IF(G43<=H43,"REPOR ESTOQUE","OK"),""))
A44: =IFERROR(FILTRO(PRODUTOS!A44:A1000,PRODUTOS!A44:A1000<>""),"") | B44: =IF(A44="","",IFERROR(VLOOKUP(A44,PRODUTOS!A:B,2,FALSE),"")) | C44: =IF(A44="","",IFERROR(VLOOKUP(A44,PRODUTOS!A:C,3,FALSE),"")) | E44: =IF(A44="","",IFERROR(SUMIFS('MOVIMENTAÇÕES'!D:D,'MOVIMENTAÇÕES'!C:C,A44,'MOVIMENTAÇÕES'!B:B,"Entrada"),"")) | F44: =IF(A44="","",IFERROR(SUMIFS('MOVIMENTAÇÕES'!D:D,'MOVIMENTAÇÕES'!C:C,A44,'MOVIMENTAÇÕES'!B:B,"Saída"),"")) | G44: =IF(A44="","",IFERROR(D44+E44-F44,"")) | H44: =IF(A44="","",VLOOKUP(A44,PRODUTOS!A:G,7,FALSE)) | I44: =IF(A44="","",IFERROR(IF(G44<=H44,"REPOR ESTOQUE","OK"),""))
A45: =IFERROR(FILTRO(PRODUTOS!A45:A1000,PRODUTOS!A45:A1000<>""),"") | B45: =IF(A45="","",IFERROR(VLOOKUP(A45,PRODUTOS!A:B,2,FALSE),"")) | C45: =IF(A45="","",IFERROR(VLOOKUP(A45,PRODUTOS!A:C,3,FALSE),"")) | E45: =IF(A45="","",IFERROR(SUMIFS('MOVIMENTAÇÕES'!D:D,'MOVIMENTAÇÕES'!C:C,A45,'MOVIMENTAÇÕES'!B:B,"Entrada"),"")) | G45: =IF(A45="","",IFERROR(D45+E45-F45,"")) | H45: =IF(A45="","",VLOOKUP(A45,PRODUTOS!A:G,7,FALSE)) | I45: =IF(A45="","",IFERROR(IF(G45<=H45,"REPOR ESTOQUE","OK"),""))
A46: =IFERROR(FILTRO(PRODUTOS!A46:A1000,PRODUTOS!A46:A1000<>""),"") | B46: =IF(A46="","",IFERROR(VLOOKUP(A46,PRODUTOS!A:B,2,FALSE),"")) | C46: =IF(A46="","",IFERROR(VLOOKUP(A46,PRODUTOS!A:C,3,FALSE),"")) | E46: =IF(A46="","",IFERROR(SUMIFS('MOVIMENTAÇÕES'!D:D,'MOVIMENTAÇÕES'!C:C,A46,'MOVIMENTAÇÕES'!B:B,"Entrada"),"")) | G46: =IF(A46="","",IFERROR(D46+E46-F46,"")) | H46: =IF(A46="","",VLOOKUP(A46,PRODUTOS!A:G,7,FALSE)) | I46: =IF(A46="","",IFERROR(IF(G46<=H46,"REPOR ESTOQUE","OK"),""))
...

Sheet DASHBOARD 
A1: SISTEMA DE GESTÃO DE ESTOQUE
A3: Total de Produtos | B3: Unidades em Estoque | C3: Produtos para Repor | D3: Total de Saídas
A4: =COUNTA(PRODUTOS!A2:A1000) -> 3 | B4: =SUM(ESTOQUE!G2:G1000) -> 32 | C4: =COUNTIF(ESTOQUE!I2:I1000,"REPOR ESTOQUE") -> 1 | D4: =SUM(ESTOQUE!F2:F1000) -> 50
